Workbook

Sheet Dashboard
A1: TexaWave ERP - Finance Module Full Test Status Dashboard
A2: Suite: Full Finance Module & Claim Lifecycle Verification (19 sheets, 150 tests covering all controllers, pages & ledgers) | As of 29-Oct-26
A4: Total Tests | C4: Completed / PASS | E4: % Tests Done | G4: Blocked | I4: Need to Discuss / Fail | K4: Pending
A5: =COUNTA('Employee Expense Claims'!$A$5:$A$14)+COUNTA('HR Expense Approval'!$A$5:$A$12)+COUNTA('Admin Claim Conversion'!$A$5:$A$12)+COUNTA('Finance Expenses'!$A$5:$A$16)+COUNTA('Expense Category Consistency'!$A$5:$A$12)+COUNTA('Expense Reimbursement'!$A$5:$A$10)+COUNTA('Payments Received'!$A$5:$A$16)+COUNTA('Payments Made'!$A$5:$A$14)+COUNTA('Bank Accounts'!$A$5:$A$12)+COUNTA('Bank Transactions'!$A$5:$A$12)+COUNTA('General Ledger & Journal'!$A$5:$A$14)+COUNTA('GST & Tax Integration'!$A$5:$A$14)+COUNTA('Chart of Accounts & Reports'!$A$5:$A$12)+COUNTA('Browser UI Verification'!$A$5:$A$18)+COUNTA('Cross-Module End-to-End'!$A$5:$A$10)+COUNTA('Regression & Negative Tests'!$A$5:$A$16) -> 150 | C5: =COUNTIF('Employee Expense Claims'!$H$5:$H$14,"Completed")+COUNTIF('Employee Expense Claims'!$H$5:$H$14,"PASS")+COUNTIF('HR Expense Approval'!$H$5:$H$12,"Completed")+COUNTIF('HR Expense Approval'!$H$5:$H$12,"PASS")+COUNTIF('Admin Claim Conversion'!$H$5:$H$12,"Completed")+COUNTIF('Admin Claim Conversion'!$H$5:$H$12,"PASS")+COUNTIF('Finance Expenses'!$H$5:$H$16,"Completed")+COUNTIF('Finance Expenses'!$H$5:$H$16,"PASS")+COUNTIF('Expense Category Consistency'!$H$5:$H$12,"Completed")+COUNTIF('Expense Category Consistency'!$H$5:$H$12,"PASS")+COUNTIF('Expense Reimbursement'!$H$5:$H$10,"Completed")+COUNTIF('Expense Reimbursement'!$H$5:$H$10,"PASS")+COUNTIF('Payments Received'!$H$5:$H$16,"Completed")+COUNTIF('Payments Received'!$H$5:$H$16,"PASS")+COUNTIF('Payments Made'!$H$5:$H$14,"Completed")+COUNTIF('Payments Made'!$H$5:$H$14,"PASS")+COUNTIF('Bank Accounts'!$H$5:$H$12,"Completed")+COUNTIF('Bank Accounts'!$H$5:$H$12,"PASS")+COUNTIF('Bank Transactions'!$H$5:$H$12,"Completed")+COUNTIF('Bank Transactions'!$H$5:$H$12,"PASS")+COUNTIF('General Ledger & Journal'!$H$5:$H$14,"Completed")+COUNTIF('General Ledger & Journal'!$H$5:$H$14,"PASS")+COUNTIF('GST & Tax Integration'!$H$5:$H$14,"Completed")+COUNTIF('GST & Tax Integration'!$H$5:$H$14,"PASS")+COUNTIF('Chart of Accounts & Reports'!$H$5:$H$12,"Completed")+COUNTIF('Chart of Accounts & Reports'!$H$5:$H$12,"PASS")+COUNTIF('Browser UI Verification'!$H$5:$H$18,"Completed")+COUNTIF('Browser UI Verification'!$H$5:$H$18,"PASS")+COUNTIF('Cross-Module End-to-End'!$H$5:$H$10,"Completed")+COUNTIF('Cross-Module End-to-End'!$H$5:$H$10,"PASS")+COUNTIF('Regression & Negative Tests'!$H$5:$H$16,"Completed")+COUNTIF('Regression & Negative Tests'!$H$5:$H$16,"PASS") -> 150 | E5: =IFERROR(AVERAGE('Employee Expense Claims'!$I$5:$I$14,'HR Expense Approval'!$I$5:$I$12,'Admin Claim Conversion'!$I$5:$I$12,'Finance Expenses'!$I$5:$I$16,'Expense Category Consistency'!$I$5:$I$12,'Expense Reimbursement'!$I$5:$I$10,'Payments Received'!$I$5:$I$16,'Payments Made'!$I$5:$I$14,'Bank Accounts'!$I$5:$I$12,'Bank Transactions'!$I$5:$I$12,'General Ledger & Journal'!$I$5:$I$14,'GST & Tax Integration'!$I$5:$I$14,'Chart of Accounts & Reports'!$I$5:$I$12,'Browser UI Verification'!$I$5:$I$18,'Cross-Module End-to-End'!$I$5:$I$10,'Regression & Negative Tests'!$I$5:$I$16),0) -> 1 | G5: =COUNTIF('Employee Expense Claims'!$H$5:$H$14,"Blocked")+COUNTIF('Employee Expense Claims'!$H$5:$H$14,"BLOCKED")+COUNTIF('HR Expense Approval'!$H$5:$H$12,"Blocked")+COUNTIF('HR Expense Approval'!$H$5:$H$12,"BLOCKED")+COUNTIF('Admin Claim Conversion'!$H$5:$H$12,"Blocked")+COUNTIF('Admin Claim Conversion'!$H$5:$H$12,"BLOCKED")+COUNTIF('Finance Expenses'!$H$5:$H$16,"Blocked")+COUNTIF('Finance Expenses'!$H$5:$H$16,"BLOCKED")+COUNTIF('Expense Category Consistency'!$H$5:$H$12,"Blocked")+COUNTIF('Expense Category Consistency'!$H$5:$H$12,"BLOCKED")+COUNTIF('Expense Reimbursement'!$H$5:$H$10,"Blocked")+COUNTIF('Expense Reimbursement'!$H$5:$H$10,"BLOCKED")+COUNTIF('Payments Received'!$H$5:$H$16,"Blocked")+COUNTIF('Payments Received'!$H$5:$H$16,"BLOCKED")+COUNTIF('Payments Made'!$H$5:$H$14,"Blocked")+COUNTIF('Payments Made'!$H$5:$H$14,"BLOCKED")+COUNTIF('Bank Accounts'!$H$5:$H$12,"Blocked")+COUNTIF('Bank Accounts'!$H$5:$H$12,"BLOCKED")+COUNTIF('Bank Transactions'!$H$5:$H$12,"Blocked")+COUNTIF('Bank Transactions'!$H$5:$H$12,"BLOCKED")+COUNTIF('General Ledger & Journal'!$H$5:$H$14,"Blocked")+COUNTIF('General Ledger & Journal'!$H$5:$H$14,"BLOCKED")+COUNTIF('GST & Tax Integration'!$H$5:$H$14,"Blocked")+COUNTIF('GST & Tax Integration'!$H$5:$H$14,"BLOCKED")+COUNTIF('Chart of Accounts & Reports'!$H$5:$H$12,"Blocked")+COUNTIF('Chart of Accounts & Reports'!$H$5:$H$12,"BLOCKED")+COUNTIF('Browser UI Verification'!$H$5:$H$18,"Blocked")+COUNTIF('Browser UI Verification'!$H$5:$H$18,"BLOCKED")+COUNTIF('Cross-Module End-to-End'!$H$5:$H$10,"Blocked")+COUNTIF('Cross-Module End-to-End'!$H$5:$H$10,"BLOCKED")+COUNTIF('Regression & Negative Tests'!$H$5:$H$16,"Blocked")+COUNTIF('Regression & Negative Tests'!$H$5:$H$16,"BLOCKED") -> 0 | I5: =COUNTIF('Employee Expense Claims'!$H$5:$H$14,"Need to Discuss")+COUNTIF('Employee Expense Claims'!$H$5:$H$14,"FAIL")+COUNTIF('HR Expense Approval'!$H$5:$H$12,"Need to Discuss")+COUNTIF('HR Expense Approval'!$H$5:$H$12,"FAIL")+COUNTIF('Admin Claim Conversion'!$H$5:$H$12,"Need to Discuss")+COUNTIF('Admin Claim Conversion'!$H$5:$H$12,"FAIL")+COUNTIF('Finance Expenses'!$H$5:$H$16,"Need to Discuss")+COUNTIF('Finance Expenses'!$H$5:$H$16,"FAIL")+COUNTIF('Expense Category Consistency'!$H$5:$H$12,"Need to Discuss")+COUNTIF('Expense Category Consistency'!$H$5:$H$12,"FAIL")+COUNTIF('Expense Reimbursement'!$H$5:$H$10,"Need to Discuss")+COUNTIF('Expense Reimbursement'!$H$5:$H$10,"FAIL")+COUNTIF('Payments Received'!$H$5:$H$16,"Need to Discuss")+COUNTIF('Payments Received'!$H$5:$H$16,"FAIL")+COUNTIF('Payments Made'!$H$5:$H$14,"Need to Discuss")+COUNTIF('Payments Made'!$H$5:$H$14,"FAIL")+COUNTIF('Bank Accounts'!$H$5:$H$12,"Need to Discuss")+COUNTIF('Bank Accounts'!$H$5:$H$12,"FAIL")+COUNTIF('Bank Transactions'!$H$5:$H$12,"Need to Discuss")+COUNTIF('Bank Transactions'!$H$5:$H$12,"FAIL")+COUNTIF('General Ledger & Journal'!$H$5:$H$14,"Need to Discuss")+COUNTIF('General Ledger & Journal'!$H$5:$H$14,"FAIL")+COUNTIF('GST & Tax Integration'!$H$5:$H$14,"Need to Discuss")+COUNTIF('GST & Tax Integration'!$H$5:$H$14,"FAIL")+COUNTIF('Chart of Accounts & Reports'!$H$5:$H$12,"Need to Discuss")+COUNTIF('Chart of Accounts & Reports'!$H$5:$H$12,"FAIL")+COUNTIF('Browser UI Verification'!$H$5:$H$18,"Need to Discuss")+COUNTIF('Browser UI Verification'!$H$5:$H$18,"FAIL")+COUNTIF('Cross-Module End-to-End'!$H$5:$H$10,"Need to Discuss")+COUNTIF('Cross-Module End-to-End'!$H$5:$H$10,"FAIL")+COUNTIF('Regression & Negative Tests'!$H$5:$H$16,"Need to Discuss")+COUNTIF('Regression & Negative Tests'!$H$5:$H$16,"FAIL") -> 0 | K5: =COUNTIF('Employee Expense Claims'!$H$5:$H$14,"Pending")+COUNTIF('Employee Expense Claims'!$H$5:$H$14,"PENDING")+COUNTIF('HR Expense Approval'!$H$5:$H$12,"Pending")+COUNTIF('HR Expense Approval'!$H$5:$H$12,"PENDING")+COUNTIF('Admin Claim Conversion'!$H$5:$H$12,"Pending")+COUNTIF('Admin Claim Conversion'!$H$5:$H$12,"PENDING")+COUNTIF('Finance Expenses'!$H$5:$H$16,"Pending")+COUNTIF('Finance Expenses'!$H$5:$H$16,"PENDING")+COUNTIF('Expense Category Consistency'!$H$5:$H$12,"Pending")+COUNTIF('Expense Category Consistency'!$H$5:$H$12,"PENDING")+COUNTIF('Expense Reimbursement'!$H$5:$H$10,"Pending")+COUNTIF('Expense Reimbursement'!$H$5:$H$10,"PENDING")+COUNTIF('Payments Received'!$H$5:$H$16,"Pending")+COUNTIF('Payments Received'!$H$5:$H$16,"PENDING")+COUNTIF('Payments Made'!$H$5:$H$14,"Pending")+COUNTIF('Payments Made'!$H$5:$H$14,"PENDING")+COUNTIF('Bank Accounts'!$H$5:$H$12,"Pending")+COUNTIF('Bank Accounts'!$H$5:$H$12,"PENDING")+COUNTIF('Bank Transactions'!$H$5:$H$12,"Pending")+COUNTIF('Bank Transactions'!$H$5:$H$12,"PENDING")+COUNTIF('General Ledger & Journal'!$H$5:$H$14,"Pending")+COUNTIF('General Ledger & Journal'!$H$5:$H$14,"PENDING")+COUNTIF('GST & Tax Integration'!$H$5:$H$14,"Pending")+COUNTIF('GST & Tax Integration'!$H$5:$H$14,"PENDING")+COUNTIF('Chart of Accounts & Reports'!$H$5:$H$12,"Pending")+COUNTIF('Chart of Accounts & Reports'!$H$5:$H$12,"PENDING")+COUNTIF('Browser UI Verification'!$H$5:$H$18,"Pending")+COUNTIF('Browser UI Verification'!$H$5:$H$18,"PENDING")+COUNTIF('Cross-Module End-to-End'!$H$5:$H$10,"Pending")+COUNTIF('Cross-Module End-to-End'!$H$5:$H$10,"PENDING")+COUNTIF('Regression & Negative Tests'!$H$5:$H$16,"Pending")+COUNTIF('Regression & Negative Tests'!$H$5:$H$16,"PENDING") -> 0
A7: STATUS BREAKDOWN | F7: RESULTS BY MODULE & TEST SUITE
A8: Status | B8: Count | C8: % of Total | D8: Weight | F8: Module / Test Suite | G8: Total Tests | H8: Completed / Pass | I8: Pending | J8: Blocked / Fail | K8: % Done | L8: Status
A9: Completed | B9: =COUNTIF('Employee Expense Claims'!$H$5:$H$14,"Completed")+COUNTIF('Employee Expense Claims'!$H$5:$H$14,"PASS")+COUNTIF('HR Expense Approval'!$H$5:$H$12,"Completed")+COUNTIF('HR Expense Approval'!$H$5:$H$12,"PASS")+COUNTIF('Admin Claim Conversion'!$H$5:$H$12,"Completed")+COUNTIF('Admin Claim Conversion'!$H$5:$H$12,"PASS")+COUNTIF('Finance Expenses'!$H$5:$H$16,"Completed")+COUNTIF('Finance Expenses'!$H$5:$H$16,"PASS")+COUNTIF('Expense Category Consistency'!$H$5:$H$12,"Completed")+COUNTIF('Expense Category Consistency'!$H$5:$H$12,"PASS")+COUNTIF('Expense Reimbursement'!$H$5:$H$10,"Completed")+COUNTIF('Expense Reimbursement'!$H$5:$H$10,"PASS")+COUNTIF('Payments Received'!$H$5:$H$16,"Completed")+COUNTIF('Payments Received'!$H$5:$H$16,"PASS")+COUNTIF('Payments Made'!$H$5:$H$14,"Completed")+COUNTIF('Payments Made'!$H$5:$H$14,"PASS")+COUNTIF('Bank Accounts'!$H$5:$H$12,"Completed")+COUNTIF('Bank Accounts'!$H$5:$H$12,"PASS")+COUNTIF('Bank Transactions'!$H$5:$H$12,"Completed")+COUNTIF('Bank Transactions'!$H$5:$H$12,"PASS")+COUNTIF('General Ledger & Journal'!$H$5:$H$14,"Completed")+COUNTIF('General Ledger & Journal'!$H$5:$H$14,"PASS")+COUNTIF('GST & Tax Integration'!$H$5:$H$14,"Completed")+COUNTIF('GST & Tax Integration'!$H$5:$H$14,"PASS")+COUNTIF('Chart of Accounts & Reports'!$H$5:$H$12,"Completed")+COUNTIF('Chart of Accounts & Reports'!$H$5:$H$12,"PASS")+COUNTIF('Browser UI Verification'!$H$5:$H$18,"Completed")+COUNTIF('Browser UI Verification'!$H$5:$H$18,"PASS")+COUNTIF('Cross-Module End-to-End'!$H$5:$H$10,"Completed")+COUNTIF('Cross-Module End-to-End'!$H$5:$H$10,"PASS")+COUNTIF('Regression & Negative Tests'!$H$5:$H$16,"Completed")+COUNTIF('Regression & Negative Tests'!$H$5:$H$16,"PASS") -> 150 | C9: =IFERROR(B9/$A$5,0) -> 1 | D9: =IF(A9="Completed",B9,IF(A9="In Progress",B9*0.5,0)) -> 150 | F9: Employee Expense Claims | G9: =COUNTA('Employee Expense Claims'!$A$5:$A$14) -> 10 | H9: =COUNTIF('Employee Expense Claims'!$H$5:$H$14,"Completed")+COUNTIF('Employee Expense Claims'!$H$5:$H$14,"PASS") -> 10 | I9: =COUNTIF('Employee Expense Claims'!$H$5:$H$14,"Pending")+COUNTIF('Employee Expense Claims'!$H$5:$H$14,"PENDING") -> 0 | J9: =COUNTIF('Employee Expense Claims'!$H$5:$H$14,"Blocked")+COUNTIF('Employee Expense Claims'!$H$5:$H$14,"FAIL") -> 0 | K9: =IFERROR(H9/G9,0) -> 1 | L9: =IF(H9=G9,"Completed",IF(J9>0,"Blocked",IF(H9>0,"In Progress","Pending"))) -> Completed
A10: In Progress | B10: =0 -> 0 | C10: =IFERROR(B10/$A$5,0) -> 0 | D10: =IF(A10="Completed",B10,IF(A10="In Progress",B10*0.5,0)) -> 0 | F10: HR Expense Approval | G10: =COUNTA('HR Expense Approval'!$A$5:$A$12) -> 8 | H10: =COUNTIF('HR Expense Approval'!$H$5:$H$12,"Completed")+COUNTIF('HR Expense Approval'!$H$5:$H$12,"PASS") -> 8 | I10: =COUNTIF('HR Expense Approval'!$H$5:$H$12,"Pending")+COUNTIF('HR Expense Approval'!$H$5:$H$12,"PENDING") -> 0 | J10: =COUNTIF('HR Expense Approval'!$H$5:$H$12,"Blocked")+COUNTIF('HR Expense Approval'!$H$5:$H$12,"FAIL") -> 0 | K10: =IFERROR(H10/G10,0) -> 1 | L10: =IF(H10=G10,"Completed",IF(J10>0,"Blocked",IF(H10>0,"In Progress","Pending"))) -> Completed
A11: Pending | B11: =COUNTIF('Employee Expense Claims'!$H$5:$H$14,"Pending")+COUNTIF('Employee Expense Claims'!$H$5:$H$14,"PENDING")+COUNTIF('HR Expense Approval'!$H$5:$H$12,"Pending")+COUNTIF('HR Expense Approval'!$H$5:$H$12,"PENDING")+COUNTIF('Admin Claim Conversion'!$H$5:$H$12,"Pending")+COUNTIF('Admin Claim Conversion'!$H$5:$H$12,"PENDING")+COUNTIF('Finance Expenses'!$H$5:$H$16,"Pending")+COUNTIF('Finance Expenses'!$H$5:$H$16,"PENDING")+COUNTIF('Expense Category Consistency'!$H$5:$H$12,"Pending")+COUNTIF('Expense Category Consistency'!$H$5:$H$12,"PENDING")+COUNTIF('Expense Reimbursement'!$H$5:$H$10,"Pending")+COUNTIF('Expense Reimbursement'!$H$5:$H$10,"PENDING")+COUNTIF('Payments Received'!$H$5:$H$16,"Pending")+COUNTIF('Payments Received'!$H$5:$H$16,"PENDING")+COUNTIF('Payments Made'!$H$5:$H$14,"Pending")+COUNTIF('Payments Made'!$H$5:$H$14,"PENDING")+COUNTIF('Bank Accounts'!$H$5:$H$12,"Pending")+COUNTIF('Bank Accounts'!$H$5:$H$12,"PENDING")+COUNTIF('Bank Transactions'!$H$5:$H$12,"Pending")+COUNTIF('Bank Transactions'!$H$5:$H$12,"PENDING")+COUNTIF('General Ledger & Journal'!$H$5:$H$14,"Pending")+COUNTIF('General Ledger & Journal'!$H$5:$H$14,"PENDING")+COUNTIF('GST & Tax Integration'!$H$5:$H$14,"Pending")+COUNTIF('GST & Tax Integration'!$H$5:$H$14,"PENDING")+COUNTIF('Chart of Accounts & Reports'!$H$5:$H$12,"Pending")+COUNTIF('Chart of Accounts & Reports'!$H$5:$H$12,"PENDING")+COUNTIF('Browser UI Verification'!$H$5:$H$18,"Pending")+COUNTIF('Browser UI Verification'!$H$5:$H$18,"PENDING")+COUNTIF('Cross-Module End-to-End'!$H$5:$H$10,"Pending")+COUNTIF('Cross-Module End-to-End'!$H$5:$H$10,"PENDING")+COUNTIF('Regression & Negative Tests'!$H$5:$H$16,"Pending")+COUNTIF('Regression & Negative Tests'!$H$5:$H$16,"PENDING") -> 0 | C11: =IFERROR(B11/$A$5,0) -> 0 | D11: =IF(A11="Completed",B11,IF(A11="In Progress",B11*0.5,0)) -> 0 | F11: Admin Claim Conversion | G11: =COUNTA('Admin Claim Conversion'!$A$5:$A$12) -> 8 | H11: =COUNTIF('Admin Claim Conversion'!$H$5:$H$12,"Completed")+COUNTIF('Admin Claim Conversion'!$H$5:$H$12,"PASS") -> 8 | I11: =COUNTIF('Admin Claim Conversion'!$H$5:$H$12,"Pending")+COUNTIF('Admin Claim Conversion'!$H$5:$H$12,"PENDING") -> 0 | J11: =COUNTIF('Admin Claim Conversion'!$H$5:$H$12,"Blocked")+COUNTIF('Admin Claim Conversion'!$H$5:$H$12,"FAIL") -> 0 | K11: =IFERROR(H11/G11,0) -> 1 | L11: =IF(H11=G11,"Completed",IF(J11>0,"Blocked",IF(H11>0,"In Progress","Pending"))) -> Completed
A12: Blocked | B12: =COUNTIF('Employee Expense Claims'!$H$5:$H$14,"Blocked")+COUNTIF('Employee Expense Claims'!$H$5:$H$14,"BLOCKED")+COUNTIF('HR Expense Approval'!$H$5:$H$12,"Blocked")+COUNTIF('HR Expense Approval'!$H$5:$H$12,"BLOCKED")+COUNTIF('Admin Claim Conversion'!$H$5:$H$12,"Blocked")+COUNTIF('Admin Claim Conversion'!$H$5:$H$12,"BLOCKED")+COUNTIF('Finance Expenses'!$H$5:$H$16,"Blocked")+COUNTIF('Finance Expenses'!$H$5:$H$16,"BLOCKED")+COUNTIF('Expense Category Consistency'!$H$5:$H$12,"Blocked")+COUNTIF('Expense Category Consistency'!$H$5:$H$12,"BLOCKED")+COUNTIF('Expense Reimbursement'!$H$5:$H$10,"Blocked")+COUNTIF('Expense Reimbursement'!$H$5:$H$10,"BLOCKED")+COUNTIF('Payments Received'!$H$5:$H$16,"Blocked")+COUNTIF('Payments Received'!$H$5:$H$16,"BLOCKED")+COUNTIF('Payments Made'!$H$5:$H$14,"Blocked")+COUNTIF('Payments Made'!$H$5:$H$14,"BLOCKED")+COUNTIF('Bank Accounts'!$H$5:$H$12,"Blocked")+COUNTIF('Bank Accounts'!$H$5:$H$12,"BLOCKED")+COUNTIF('Bank Transactions'!$H$5:$H$12,"Blocked")+COUNTIF('Bank Transactions'!$H$5:$H$12,"BLOCKED")+COUNTIF('General Ledger & Journal'!$H$5:$H$14,"Blocked")+COUNTIF('General Ledger & Journal'!$H$5:$H$14,"BLOCKED")+COUNTIF('GST & Tax Integration'!$H$5:$H$14,"Blocked")+COUNTIF('GST & Tax Integration'!$H$5:$H$14,"BLOCKED")+COUNTIF('Chart of Accounts & Reports'!$H$5:$H$12,"Blocked")+COUNTIF('Chart of Accounts & Reports'!$H$5:$H$12,"BLOCKED")+COUNTIF('Browser UI Verification'!$H$5:$H$18,"Blocked")+COUNTIF('Browser UI Verification'!$H$5:$H$18,"BLOCKED")+COUNTIF('Cross-Module End-to-End'!$H$5:$H$10,"Blocked")+COUNTIF('Cross-Module End-to-End'!$H$5:$H$10,"BLOCKED")+COUNTIF('Regression & Negative Tests'!$H$5:$H$16,"Blocked")+COUNTIF('Regression & Negative Tests'!$H$5:$H$16,"BLOCKED") -> 0 | C12: =IFERROR(B12/$A$5,0) -> 0 | D12: =IF(A12="Completed",B12,IF(A12="In Progress",B12*0.5,0)) -> 0 | F12: Finance Expenses | G12: =COUNTA('Finance Expenses'!$A$5:$A$16) -> 12 | H12: =COUNTIF('Finance Expenses'!$H$5:$H$16,"Completed")+COUNTIF('Finance Expenses'!$H$5:$H$16,"PASS") -> 12 | I12: =COUNTIF('Finance Expenses'!$H$5:$H$16,"Pending")+COUNTIF('Finance Expenses'!$H$5:$H$16,"PENDING") -> 0 | J12: =COUNTIF('Finance Expenses'!$H$5:$H$16,"Blocked")+COUNTIF('Finance Expenses'!$H$5:$H$16,"FAIL") -> 0 | K12: =IFERROR(H12/G12,0) -> 1 | L12: =IF(H12=G12,"Completed",IF(J12>0,"Blocked",IF(H12>0,"In Progress","Pending"))) -> Completed
A13: Need to Discuss | B13: =COUNTIF('Employee Expense Claims'!$H$5:$H$14,"Need to Discuss")+COUNTIF('Employee Expense Claims'!$H$5:$H$14,"FAIL")+COUNTIF('HR Expense Approval'!$H$5:$H$12,"Need to Discuss")+COUNTIF('HR Expense Approval'!$H$5:$H$12,"FAIL")+COUNTIF('Admin Claim Conversion'!$H$5:$H$12,"Need to Discuss")+COUNTIF('Admin Claim Conversion'!$H$5:$H$12,"FAIL")+COUNTIF('Finance Expenses'!$H$5:$H$16,"Need to Discuss")+COUNTIF('Finance Expenses'!$H$5:$H$16,"FAIL")+COUNTIF('Expense Category Consistency'!$H$5:$H$12,"Need to Discuss")+COUNTIF('Expense Category Consistency'!$H$5:$H$12,"FAIL")+COUNTIF('Expense Reimbursement'!$H$5:$H$10,"Need to Discuss")+COUNTIF('Expense Reimbursement'!$H$5:$H$10,"FAIL")+COUNTIF('Payments Received'!$H$5:$H$16,"Need to Discuss")+COUNTIF('Payments Received'!$H$5:$H$16,"FAIL")+COUNTIF('Payments Made'!$H$5:$H$14,"Need to Discuss")+COUNTIF('Payments Made'!$H$5:$H$14,"FAIL")+COUNTIF('Bank Accounts'!$H$5:$H$12,"Need to Discuss")+COUNTIF('Bank Accounts'!$H$5:$H$12,"FAIL")+COUNTIF('Bank Transactions'!$H$5:$H$12,"Need to Discuss")+COUNTIF('Bank Transactions'!$H$5:$H$12,"FAIL")+COUNTIF('General Ledger & Journal'!$H$5:$H$14,"Need to Discuss")+COUNTIF('General Ledger & Journal'!$H$5:$H$14,"FAIL")+COUNTIF('GST & Tax Integration'!$H$5:$H$14,"Need to Discuss")+COUNTIF('GST & Tax Integration'!$H$5:$H$14,"FAIL")+COUNTIF('Chart of Accounts & Reports'!$H$5:$H$12,"Need to Discuss")+COUNTIF('Chart of Accounts & Reports'!$H$5:$H$12,"FAIL")+COUNTIF('Browser UI Verification'!$H$5:$H$18,"Need to Discuss")+COUNTIF('Browser UI Verification'!$H$5:$H$18,"FAIL")+COUNTIF('Cross-Module End-to-End'!$H$5:$H$10,"Need to Discuss")+COUNTIF('Cross-Module End-to-End'!$H$5:$H$10,"FAIL")+COUNTIF('Regression & Negative Tests'!$H$5:$H$16,"Need to Discuss")+COUNTIF('Regression & Negative Tests'!$H$5:$H$16,"FAIL") -> 0 | C13: =IFERROR(B13/$A$5,0) -> 0 | D13: =IF(A13="Completed",B13,IF(A13="In Progress",B13*0.5,0)) -> 0 | F13: Expense Category Consistency | G13: =COUNTA('Expense Category Consistency'!$A$5:$A$12) -> 8 | H13: =COUNTIF('Expense Category Consistency'!$H$5:$H$12,"Completed")+COUNTIF('Expense Category Consistency'!$H$5:$H$12,"PASS") -> 8 | I13: =COUNTIF('Expense Category Consistency'!$H$5:$H$12,"Pending")+COUNTIF('Expense Category Consistency'!$H$5:$H$12,"PENDING") -> 0 | J13: =COUNTIF('Expense Category Consistency'!$H$5:$H$12,"Blocked")+COUNTIF('Expense Category Consistency'!$H$5:$H$12,"FAIL") -> 0 | K13: =IFERROR(H13/G13,0) -> 1 | L13: =IF(H13=G13,"Completed",IF(J13>0,"Blocked",IF(H13>0,"In Progress","Pending"))) -> Completed
A14: Not Started | B14: =0 -> 0 | C14: =IFERROR(B14/$A$5,0) -> 0 | D14: =IF(A14="Completed",B14,IF(A14="In Progress",B14*0.5,0)) -> 0 | F14: Expense Reimbursement | G14: =COUNTA('Expense Reimbursement'!$A$5:$A$10) -> 6 | H14: =COUNTIF('Expense Reimbursement'!$H$5:$H$10,"Completed")+COUNTIF('Expense Reimbursement'!$H$5:$H$10,"PASS") -> 6 | I14: =COUNTIF('Expense Reimbursement'!$H$5:$H$10,"Pending")+COUNTIF('Expense Reimbursement'!$H$5:$H$10,"PENDING") -> 0 | J14: =COUNTIF('Expense Reimbursement'!$H$5:$H$10,"Blocked")+COUNTIF('Expense Reimbursement'!$H$5:$H$10,"FAIL") -> 0 | K14: =IFERROR(H14/G14,0) -> 1 | L14: =IF(H14=G14,"Completed",IF(J14>0,"Blocked",IF(H14>0,"In Progress","Pending"))) -> Completed
A15: Total | B15: =SUM(B9:B14) -> 150 | C15: =SUM(C9:C14) -> 1 | D15: =SUM(D9:D14) -> 150 | F15: Payments Received | G15: =COUNTA('Payments Received'!$A$5:$A$16) -> 12 | H15: =COUNTIF('Payments Received'!$H$5:$H$16,"Completed")+COUNTIF('Payments Received'!$H$5:$H$16,"PASS") -> 12 | I15: =COUNTIF('Payments Received'!$H$5:$H$16,"Pending")+COUNTIF('Payments Received'!$H$5:$H$16,"PENDING") -> 0 | J15: =COUNTIF('Payments Received'!$H$5:$H$16,"Blocked")+COUNTIF('Payments Received'!$H$5:$H$16,"FAIL") -> 0 | K15: =IFERROR(H15/G15,0) -> 1 | L15: =IF(H15=G15,"Completed",IF(J15>0,"Blocked",IF(H15>0,"In Progress","Pending"))) -> Completed
F16: Payments Made | G16: =COUNTA('Payments Made'!$A$5:$A$14) -> 10 | H16: =COUNTIF('Payments Made'!$H$5:$H$14,"Completed")+COUNTIF('Payments Made'!$H$5:$H$14,"PASS") -> 10 | I16: =COUNTIF('Payments Made'!$H$5:$H$14,"Pending")+COUNTIF('Payments Made'!$H$5:$H$14,"PENDING") -> 0 | J16: =COUNTIF('Payments Made'!$H$5:$H$14,"Blocked")+COUNTIF('Payments Made'!$H$5:$H$14,"FAIL") -> 0 | K16: =IFERROR(H16/G16,0) -> 1 | L16: =IF(H16=G16,"Completed",IF(J16>0,"Blocked",IF(H16>0,"In Progress","Pending"))) -> Completed
F17: Bank Accounts | G17: =COUNTA('Bank Accounts'!$A$5:$A$12) -> 8 | H17: =COUNTIF('Bank Accounts'!$H$5:$H$12,"Completed")+COUNTIF('Bank Accounts'!$H$5:$H$12,"PASS") -> 8 | I17: =COUNTIF('Bank Accounts'!$H$5:$H$12,"Pending")+COUNTIF('Bank Accounts'!$H$5:$H$12,"PENDING") -> 0 | J17: =COUNTIF('Bank Accounts'!$H$5:$H$12,"Blocked")+COUNTIF('Bank Accounts'!$H$5:$H$12,"FAIL") -> 0 | K17: =IFERROR(H17/G17,0) -> 1 | L17: =IF(H17=G17,"Completed",IF(J17>0,"Blocked",IF(H17>0,"In Progress","Pending"))) -> Completed
F18: Bank Transactions | G18: =COUNTA('Bank Transactions'!$A$5:$A$12) -> 8 | H18: =COUNTIF('Bank Transactions'!$H$5:$H$12,"Completed")+COUNTIF('Bank Transactions'!$H$5:$H$12,"PASS") -> 8 | I18: =COUNTIF('Bank Transactions'!$H$5:$H$12,"Pending")+COUNTIF('Bank Transactions'!$H$5:$H$12,"PENDING") -> 0 | J18: =COUNTIF('Bank Transactions'!$H$5:$H$12,"Blocked")+COUNTIF('Bank Transactions'!$H$5:$H$12,"FAIL") -> 0 | K18: =IFERROR(H18/G18,0) -> 1 | L18: =IF(H18=G18,"Completed",IF(J18>0,"Blocked",IF(H18>0,"In Progress","Pending"))) -> Completed
F19: General Ledger & Journal | G19: =COUNTA('General Ledger & Journal'!$A$5:$A$14) -> 10 | H19: =COUNTIF('General Ledger & Journal'!$H$5:$H$14,"Completed")+COUNTIF('General Ledger & Journal'!$H$5:$H$14,"PASS") -> 10 | I19: =COUNTIF('General Ledger & Journal'!$H$5:$H$14,"Pending")+COUNTIF('General Ledger & Journal'!$H$5:$H$14,"PENDING") -> 0 | J19: =COUNTIF('General Ledger & Journal'!$H$5:$H$14,"Blocked")+COUNTIF('General Ledger & Journal'!$H$5:$H$14,"FAIL") -> 0 | K19: =IFERROR(H19/G19,0) -> 1 | L19: =IF(H19=G19,"Completed",IF(J19>0,"Blocked",IF(H19>0,"In Progress","Pending"))) -> Completed
F20: GST & Tax Integration | G20: =COUNTA('GST & Tax Integration'!$A$5:$A$14) -> 10 | H20: =COUNTIF('GST & Tax Integration'!$H$5:$H$14,"Completed")+COUNTIF('GST & Tax Integration'!$H$5:$H$14,"PASS") -> 10 | I20: =COUNTIF('GST & Tax Integration'!$H$5:$H$14,"Pending")+COUNTIF('GST & Tax Integration'!$H$5:$H$14,"PENDING") -> 0 | J20: =COUNTIF('GST & Tax Integration'!$H$5:$H$14,"Blocked")+COUNTIF('GST & Tax Integration'!$H$5:$H$14,"FAIL") -> 0 | K20: =IFERROR(H20/G20,0) -> 1 | L20: =IF(H20=G20,"Completed",IF(J20>0,"Blocked",IF(H20>0,"In Progress","Pending"))) -> Completed
F21: Chart of Accounts & Reports | G21: =COUNTA('Chart of Accounts & Reports'!$A$5:$A$12) -> 8 | H21: =COUNTIF('Chart of Accounts & Reports'!$H$5:$H$12,"Completed")+COUNTIF('Chart of Accounts & Reports'!$H$5:$H$12,"PASS") -> 8 | I21: =COUNTIF('Chart of Accounts & Reports'!$H$5:$H$12,"Pending")+COUNTIF('Chart of Accounts & Reports'!$H$5:$H$12,"PENDING") -> 0 | J21: =COUNTIF('Chart of Accounts & Reports'!$H$5:$H$12,"Blocked")+COUNTIF('Chart of Accounts & Reports'!$H$5:$H$12,"FAIL") -> 0 | K21: =IFERROR(H21/G21,0) -> 1 | L21: =IF(H21=G21,"Completed",IF(J21>0,"Blocked",IF(H21>0,"In Progress","Pending"))) -> Completed
F22: Browser UI Verification | G22: =COUNTA('Browser UI Verification'!$A$5:$A$18) -> 14 | H22: =COUNTIF('Browser UI Verification'!$H$5:$H$18,"Completed")+COUNTIF('Browser UI Verification'!$H$5:$H$18,"PASS") -> 14 | I22: =COUNTIF('Browser UI Verification'!$H$5:$H$18,"Pending")+COUNTIF('Browser UI Verification'!$H$5:$H$18,"PENDING") -> 0 | J22: =COUNTIF('Browser UI Verification'!$H$5:$H$18,"Blocked")+COUNTIF('Browser UI Verification'!$H$5:$H$18,"FAIL") -> 0 | K22: =IFERROR(H22/G22,0) -> 1 | L22: =IF(H22=G22,"Completed",IF(J22>0,"Blocked",IF(H22>0,"In Progress","Pending"))) -> Completed
F23: Cross-Module End-to-End | G23: =COUNTA('Cross-Module End-to-End'!$A$5:$A$10) -> 6 | H23: =COUNTIF('Cross-Module End-to-End'!$H$5:$H$10,"Completed")+COUNTIF('Cross-Module End-to-End'!$H$5:$H$10,"PASS") -> 6 | I23: =COUNTIF('Cross-Module End-to-End'!$H$5:$H$10,"Pending")+COUNTIF('Cross-Module End-to-End'!$H$5:$H$10,"PENDING") -> 0 | J23: =COUNTIF('Cross-Module End-to-End'!$H$5:$H$10,"Blocked")+COUNTIF('Cross-Module End-to-End'!$H$5:$H$10,"FAIL") -> 0 | K23: =IFERROR(H23/G23,0) -> 1 | L23: =IF(H23=G23,"Completed",IF(J23>0,"Blocked",IF(H23>0,"In Progress","Pending"))) -> Completed
F24: Regression & Negative Tests | G24: =COUNTA('Regression & Negative Tests'!$A$5:$A$16) -> 12 | H24: =COUNTIF('Regression & Negative Tests'!$H$5:$H$16,"Completed")+COUNTIF('Regression & Negative Tests'!$H$5:$H$16,"PASS") -> 12 | I24: =COUNTIF('Regression & Negative Tests'!$H$5:$H$16,"Pending")+COUNTIF('Regression & Negative Tests'!$H$5:$H$16,"PENDING") -> 0 | J24: =COUNTIF('Regression & Negative Tests'!$H$5:$H$16,"Blocked")+COUNTIF('Regression & Negative Tests'!$H$5:$H$16,"FAIL") -> 0 | K24: =IFERROR(H24/G24,0) -> 1 | L24: =IF(H24=G24,"Completed",IF(J24>0,"Blocked",IF(H24>0,"In Progress","Pending"))) -> Completed
F25: Total All Suites | G25: =SUM(G9:G24) -> 150 | H25: =SUM(H9:H24) -> 150 | I25: =SUM(I9:I24) -> 0 | J25: =SUM(J9:J24) -> 0 | K25: =IFERROR(H25/G25,0) -> 1 | L25: Completed

Sheet Test Instructions and Safety
A1: TexaWave ERP - Finance Testing Instructions & Critical Safety Rules
A2: Governance, Safety Constraints & Execution Protocol | As of 29-Oct-26
A4: 1. INVIOLABLE SAFETY PROTOCOLS
A5: 1.1 Zero Destructive Operations | B5: NEVER run DROP, TRUNCATE, DELETE, database resets, destructive migrations, or bulk data removal. Protect all historical business data.
A6: 1.2 No Permanent Purge | B6: Do not execute permanent SQL DELETE or API purge endpoints. Only soft-deletes (deletedAt populated) are tested against isolated test records.
A7: 1.3 Historical Data Protection | B7: Never use existing business financial records as disposable test data. Do not alter historical records to force tests to pass.
A8: 1.4 Git Working Tree Protection | B8: Do not commit, push, reset --hard, clean -fd, or overwrite local changes. All existing local changes must be preserved.
A9: 1.5 Secret & Credential Sanitization | B9: Never expose passwords, secret JWT tokens, or API keys in reports or workbooks. All tokens are redacted or transient.
A11: 2. TEST IDENTIFIER CONVENTION
A12: CLM-001 to CLM-010 | B12: Employee Self-Service Portal - Expense claims submission, history, and category validation
A13: HRA-001 to HRA-008 | B13: HR Management - Expense claims approvals, rejections, decision notes, and category preservation
A14: ADM-001 to ADM-008 | B14: Admin Claim Conversion - Conversion of approved claims into Finance Expenses with explicit category mapping
A15: EXP-001 to EXP-012 | B15: Finance Module - Operational expenses lifecycle, approvals, payouts, and GL posting
A16: CAT-001 to CAT-008 | B16: Expense Category Consistency - Verification of 6 canonical categories and auto-provisioning rules
A17: REIM-001 to REIM-006 | B17: Expense Reimbursement - Disbursing claim payouts, bank balance reductions, and DEBIT transaction logging
A18: REC-001 to REC-012 | B18: Payments Received - Bank Inflow Fix verification (CREDIT bank transactions), multi-invoice allocation, and void reversals
A19: PAY-001 to PAY-010 | B19: Payments Made - Supplier disbursements, bank balance deductions (DEBIT transactions), and balanced void reversals
A20: BANK-001 to BANK-008 | B20: Treasury - Company bank accounts, IFSC, opening balances, and active status toggles
A21: TXN-001 to TXN-008 | B21: Treasury - Statement feeds (DEBIT/CREDIT), balance-after tracking, and journal voucher reconciliation
A22: GL-001 to GL-010 | B22: Accounting - Journal vouchers, double-entry balancing (Debit = Credit), minimum 2-line rule, and general ledger reports
A23: GST-001 to GST-010 | B23: Taxation - GSTR-1 outward tax summary, GSTR-3B net payable, HSN summary, ITC reconciliation, and Section 17(5) tax absorption
... A27: REG-001 to REG-012 | B27: Quality Assurance - Automated Vitest suites (350 tests), database validations (65 tests), typechecks, and security boundaries
A29: 3. STATUS DEFINITIONS
A30: Completed / PASS | B30: The acceptance criteria were executed and strictly verified in the development environment with tangible evidence.
A31: In Progress | B31: Test execution has commenced but awaiting asynchronous confirmation or secondary evidence.
A32: Pending | B32: Test case is defined with prerequisites and payloads, awaiting scheduled execution.
A33: Blocked | B33: Test execution could not proceed safely due to missing prerequisites, offline dependencies, or data safety constraints.
A34: Need to Discuss / FAIL | B34: Execution revealed a defect, discrepancy, or business rule violation requiring engineering resolution.

Sheet Employee Expense Claims
A1: Employee Portal - Expense Claims Verification
A2: Self-service claim submission, history, and category selection | As of 29-Oct-26
A4: Test ID | B4: Test Method | C4: URL / Route | D4: Payload / UI Action | E4: Expected Result | F4: Steps to Execute / Verification | G4: Prerequisites / Role | H4: Status | I4: % Done | J4: Actual Result / Evidence | K4: Defect Ref | L4: Last Updated
A5: CLM-001 | B5: POST | C5: {{baseUrl}}/self-service/expense-claims | D5: { "expenseType": "Medical", "amount": 2500, "expenseDate": "2026-10-28", "description": "Health checkup and lab tests", "receiptRef": "REC-MED-091" } | E5: 201 Created; claim created with status PENDING, expenseType 'Medical', employeeId bound to caller | F5: Submit medical expense claim from employee portal; verify response body and DB persistence | G5: Employee token; employee_self_service.expense_claim.create | H5: PASS | I5: =IF(OR(H5="Completed",H5="PASS"),1,IF(H5="In Progress",0.5,0)) -> 1 | J5: 201 Created; claim #9 created with status PENDING; expenseType persisted as 'Medical' | K5: None | L5: 2026-10-29
A6: CLM-002 | B6: POST | C6: {{baseUrl}}/self-service/expense-claims | D6: { "expenseType": "Travel", "amount": 1850, "expenseDate": "2026-10-28", "description": "Client site taxi conveyance", "receiptRef": "CAB-8812" } | E6: 201 Created; claim created with status PENDING, expenseType 'Travel' | F6: Submit travel claim; verify category is preserved and not altered | G6: Employee token; employee_self_service.expense_claim.create | H6: PASS | I6: =IF(OR(H6="Completed",H6="PASS"),1,IF(H6="In Progress",0.5,0)) -> 1 | J6: 201 Created; claim #10 created with expenseType 'Travel'; amount 1850.00 | K6: None | L6: 2026-10-29
A7: CLM-003 | B7: POST | C7: {{baseUrl}}/self-service/expense-claims | D7: { "expenseType": "Food", "amount": 650, "expenseDate": "2026-10-28", "description": "Working lunch with client", "receiptRef": "REST-441" } | E7: 201 Created; claim created with status PENDING, expenseType 'Food' | F7: Submit food claim; verify status and category | G7: Employee token; employee_self_service.expense_claim.create | H7: PASS | I7: =IF(OR(H7="Completed",H7="PASS"),1,IF(H7="In Progress",0.5,0)) -> 1 | J7: 201 Created; claim #11 created with expenseType 'Food' | K7: None | L7: 2026-10-29
A8: CLM-004 | B8: POST | C8: {{baseUrl}}/self-service/expense-claims | D8: { "expenseType": "Accommodation", "amount": 4200, "expenseDate": "2026-10-28", "description": "Hotel stay during onsite audit", "receiptRef": "HTL-9921" } | E8: 201 Created; claim created with status PENDING, expenseType 'Accommodation' | F8: Submit hotel accommodation claim | G8: Employee token; employee_self_service.expense_claim.create | H8: PASS | I8: =IF(OR(H8="Completed",H8="PASS"),1,IF(H8="In Progress",0.5,0)) -> 1 | J8: 201 Created; claim #12 created with expenseType 'Accommodation' | K8: None | L8: 2026-10-29
A9: CLM-005 | B9: POST | C9: {{baseUrl}}/self-service/expense-claims | D9: { "expenseType": "Office Supplies", "amount": 890, "expenseDate": "2026-10-28", "description": "Printer ink cartridge", "receiptRef": "STAT-102" } | E9: 201 Created; claim created with status PENDING, expenseType 'Office Supplies' | F9: Submit office supplies claim | G9: Employee token; employee_self_service.expense_claim.create | H9: PASS | I9: =IF(OR(H9="Completed",H9="PASS"),1,IF(H9="In Progress",0.5,0)) -> 1 | J9: 201 Created; claim #13 created with expenseType 'Office Supplies' | K9: None | L9: 2026-10-29
A10: CLM-006 | B10: POST | C10: {{baseUrl}}/self-service/expense-claims | D10: { "expenseType": "Other", "amount": 350, "expenseDate": "2026-10-28", "description": "Courier dispatch charges", "receiptRef": "POST-552" } | E10: 201 Created; claim created with status PENDING, expenseType 'Other' | F10: Submit claim with category Other | G10: Employee token; employee_self_service.expense_claim.create | H10: PASS | I10: =IF(OR(H10="Completed",H10="PASS"),1,IF(H10="In Progress",0.5,0)) -> 1 | J10: 201 Created; claim #14 created with expenseType 'Other' | K10: None | L10: 2026-10-29
A11: CLM-007 | B11: POST | C11: {{baseUrl}}/self-service/expense-claims | D11: { "expenseType": "Travel", "amount": -500, "expenseDate": "2026-10-28", "description": "Invalid negative amount" } | E11: 400 Bad Request; validation rejects negative or zero amount | F11: Attempt submission with negative amount; verify validation error response | G11: Employee token; DTO validation | H11: PASS | I11: =IF(OR(H11="Completed",H11="PASS"),1,IF(H11="In Progress",0.5,0)) -> 1 | J11: 400 Bad Request; 'amount must be a positive number'; no record created | K11: None | L11: 2026-10-29
A12: CLM-008 | B12: POST | C12: {{baseUrl}}/self-service/expense-claims | D12: { "expenseType": "Travel", "amount": 500, "expenseDate": "2026-10-28", "description": "" } | E12: 400 Bad Request; description is required and cannot be empty | F12: Attempt submission with empty description | G12: Employee token; DTO validation | H12: PASS | I12: =IF(OR(H12="Completed",H12="PASS"),1,IF(H12="In Progress",0.5,0)) -> 1 | J12: 400 Bad Request; 'description should not be empty' | K12: None | L12: 2026-10-29
A13: CLM-009 | B13: GET | C13: {{baseUrl}}/self-service/expense-claims?page=1&limit=10 | D13: (No body) | E13: 200 OK; paginated array of expense claims belonging strictly to the authenticated employee | F13: Query self-service claims list; verify pagination meta and data privacy | G13: Employee token; employee_self_service.expense_claim.read | H13: PASS | I13: =IF(OR(H13="Completed",H13="PASS"),1,IF(H13="In Progress",0.5,0)) -> 1 | J13: 200 OK; returns items array matching employee ID with exact categories | K13: None | L13: 2026-10-29
A14: CLM-010 | B14: GET | C14: {{baseUrl}}/self-service/expense-claims/:id | D14: (No body) | E14: 200 OK for own claim; 404/403 when attempting to access another employee's claim | F14: Attempt to query claim belonging to a different employee; verify tenant/employee isolation | G14: Employee token; employee_self_service.expense_claim.read | H14: PASS | I14: =IF(OR(H14="Completed",H14="PASS"),1,IF(H14="In Progress",0.5,0)) -> 1 | J14: 404 Not Found returned when employee attempts to view another user's claim | K14: None | L14: 2026-10-29

Sheet HR Expense Approval
A1: HR Management - Expense Claims Approvals
A2: Managerial review, category preservation, approval/rejection decisions | As of 29-Oct-26
A4: Test ID | B4: Test Method | C4: URL / Route | D4: Payload / UI Action | E4: Expected Result | F4: Steps to Execute / Verification | G4: Prerequisites / Role | H4: Status | I4: % Done | J4: Actual Result / Evidence | K4: Defect Ref | L4: Last Updated
A5: HRA-001 | B5: GET | C5: {{baseUrl}}/hr/expense-claims?status=PENDING&limit=20 | D5: (No body) | E5: 200 OK; returns list of pending claims across organization with employee names and categories | F5: Query pending claims from HR manager role; verify employee relation is populated | G5: HR Manager token; hr.expense_claim.read | H5: PASS | I5: =IF(OR(H5="Completed",H5="PASS"),1,IF(H5="In Progress",0.5,0)) -> 1 | J5: 200 OK; returned pending claims with employee names, codes, and correct categories | K5: None | L5: 2026-10-29
A6: HRA-002 | B6: GET | C6: {{baseUrl}}/hr/expense-claims/:id | D6: (No body) | E6: 200 OK; claim details including amount, receipt reference, expense date, and expenseType | F6: Retrieve single claim by ID from HR panel | G6: HR Manager token; hr.expense_claim.read | H6: PASS | I6: =IF(OR(H6="Completed",H6="PASS"),1,IF(H6="In Progress",0.5,0)) -> 1 | J6: 200 OK; retrieved claim details; expenseType matches submitted category | K6: None | L6: 2026-10-29
A7: HRA-003 | B7: POST | C7: {{baseUrl}}/hr/expense-claims/:id/decision | D7: { "decision": "APPROVE", "decisionNote": "Approved per travel policy" } | E7: 200 OK; claim status transitions to APPROVED; decidedBy and decidedAt populated | F7: Approve a pending claim with decision note; verify status transition | G7: HR Manager token; hr.expense_claim.decide | H7: PASS | I7: =IF(OR(H7="Completed",H7="PASS"),1,IF(H7="In Progress",0.5,0)) -> 1 | J7: 200 OK; status updated to APPROVED; category and amount preserved intact | K7: None | L7: 2026-10-29
A8: HRA-004 | B8: POST | C8: {{baseUrl}}/hr/expense-claims/:id/decision | D8: { "decision": "REJECT", "decisionNote": "Missing original tax invoice receipt" } | E8: 200 OK; claim status transitions to REJECTED; decision note recorded | F8: Reject a pending claim; verify rejection reason persists | G8: HR Manager token; hr.expense_claim.decide | H8: PASS | I8: =IF(OR(H8="Completed",H8="PASS"),1,IF(H8="In Progress",0.5,0)) -> 1 | J8: 200 OK; status updated to REJECTED; claim cannot be converted to Finance Expense | K8: None | L8: 2026-10-29
A9: HRA-005 | B9: POST | C9: {{baseUrl}}/hr/expense-claims/:id/decision | D9: { "decision": "APPROVE", "decisionNote": "Second approval attempt" } | E9: 422 Unprocessable Entity / 400; cannot decide on an already decided claim (APPROVED/REJECTED) | F9: Attempt to approve an already approved claim; verify idempotency/immutability | G9: HR Manager token; hr.expense_claim.decide | H9: PASS | I9: =IF(OR(H9="Completed",H9="PASS"),1,IF(H9="In Progress",0.5,0)) -> 1 | J9: 400/422; 'Claim has already been decided'; duplicate decision blocked | K9: None | L9: 2026-10-29
A10: HRA-006 | B10: POST | C10: {{baseUrl}}/hr/expense-claims/:id/decision | D10: { "decision": "INVALID_STATUS" } | E10: 400 Bad Request; decision must be either APPROVE or REJECT | F10: Send invalid decision enum value | G10: HR Manager token; DTO validation | H10: PASS | I10: =IF(OR(H10="Completed",H10="PASS"),1,IF(H10="In Progress",0.5,0)) -> 1 | J10: 400 Bad Request; 'decision must be one of the following values: APPROVE, REJECT' | K10: None | L10: 2026-10-29
A11: HRA-007 | B11: POST | C11: {{baseUrl}}/hr/expense-claims/:id/decision | D11: { "decision": "APPROVE" } | E11: 403 Forbidden when invoked with basic Employee token lacking hr.expense_claim.decide | F11: Attempt approval with standard employee credentials | G11: Employee token without HR permissions | H11: PASS | I11: =IF(OR(H11="Completed",H11="PASS"),1,IF(H11="In Progress",0.5,0)) -> 1 | J11: 403 Forbidden; Access Denied; non-HR users blocked | K11: None | L11: 2026-10-29
A12: HRA-008 | B12: GET | C12: {{baseUrl}}/hr/expense-claims?status=APPROVED&limit=10 | D12: (No body) | E12: 200 OK; returns approved claims list ready for Admin/Finance conversion | F12: Query approved claims list; verify filtering by status | G12: HR Manager token; hr.expense_claim.read | H12: PASS | I12: =IF(OR(H12="Completed",H12="PASS"),1,IF(H12="In Progress",0.5,0)) -> 1 | J12: 200 OK; returns only APPROVED claims with accurate counts | K12: None | L12: 2026-10-29

Sheet Admin Claim Conversion
A1: Admin Panel - Expense Claim Conversion
A2: Conversion of approved claims into Finance Expenses with category mapping | As of 29-Oct-26
A4: Test ID | B4: Test Method | C4: URL / Route | D4: Payload / UI Action | E4: Expected Result | F4: Steps to Execute / Verification | G4: Prerequisites / Role | H4: Status | I4: % Done | J4: Actual Result / Evidence | K4: Defect Ref | L4: Last Updated
A5: ADM-001 | B5: POST | C5: {{baseUrl}}/finance/expenses/from-claim/:claimId | D5: { "notes": "Converted medical claim" } | E5: 201 Created; Finance Expense created with category 'Medical', status APPROVED, linked hrExpenseClaimId | F5: Convert approved claim with category Medical; verify Finance Expense record created and mapped | G5: Admin/Finance token; finance.expense.write; claim status APPROVED | H5: PASS | I5: =IF(OR(H5="Completed",H5="PASS"),1,IF(H5="In Progress",0.5,0)) -> 1 | J5: 201 Created; EXP-202610-0015 created with category 'Medical' (ID 11), status APPROVED | K5: None | L5: 2026-10-29
A6: ADM-002 | B6: POST | C6: {{baseUrl}}/finance/expenses/from-claim/:claimId | D6: { "notes": "Converted travel claim" } | E6: 201 Created; Finance Expense created with canonical category 'Travel & Lodging', status APPROVED | F6: Convert approved claim with category Travel; verify mapped to 'Travel & Lodging' | G6: Admin/Finance token; finance.expense.write; claim status APPROVED | H6: PASS | I6: =IF(OR(H6="Completed",H6="PASS"),1,IF(H6="In Progress",0.5,0)) -> 1 | J6: 201 Created; EXP-202610-0011 created with category 'Travel & Lodging' (ID 2) | K6: None | L6: 2026-10-29
A7: ADM-003 | B7: POST | C7: {{baseUrl}}/finance/expenses/from-claim/:claimId | D7: { "notes": "Converted food claim" } | E7: 201 Created; Finance Expense created with canonical category 'Food & Meals', status APPROVED | F7: Convert approved claim with category Food; verify mapped to 'Food & Meals' | G7: Admin/Finance token; finance.expense.write; claim status APPROVED | H7: PASS | I7: =IF(OR(H7="Completed",H7="PASS"),1,IF(H7="In Progress",0.5,0)) -> 1 | J7: 201 Created; EXP-202610-0012 created with category 'Food & Meals' (ID 12) | K7: None | L7: 2026-10-29
A8: ADM-004 | B8: POST | C8: {{baseUrl}}/finance/expenses/from-claim/:claimId | D8: { "notes": "Converted accommodation claim" } | E8: 201 Created; Finance Expense created with canonical category 'Accommodation', status APPROVED | F8: Convert approved claim with category Accommodation; verify mapped to 'Accommodation' | G8: Admin/Finance token; finance.expense.write; claim status APPROVED | H8: PASS | I8: =IF(OR(H8="Completed",H8="PASS"),1,IF(H8="In Progress",0.5,0)) -> 1 | J8: 201 Created; EXP-202610-0010 created with category 'Accommodation' (ID 13) | K8: None | L8: 2026-10-29
A9: ADM-005 | B9: POST | C9: {{baseUrl}}/finance/expenses/from-claim/:claimId | D9: { "notes": "Converted office supplies claim" } | E9: 201 Created; Finance Expense created with category 'Office Supplies', status APPROVED | F9: Convert approved claim with category Office Supplies | G9: Admin/Finance token; finance.expense.write; claim status APPROVED | H9: PASS | I9: =IF(OR(H9="Completed",H9="PASS"),1,IF(H9="In Progress",0.5,0)) -> 1 | J9: 201 Created; expense created with category 'Office Supplies' (ID 1) | K9: None | L9: 2026-10-29
A10: ADM-006 | B10: POST | C10: {{baseUrl}}/finance/expenses/from-claim/:claimId | D10: { "notes": "Duplicate conversion attempt" } | E10: 409 Conflict; a Finance expense already exists for this claim; duplicate conversion blocked | F10: Attempt to convert an already converted claim; verify duplicate prevention | G10: Claim already converted to Finance Expense | H10: PASS | I10: =IF(OR(H10="Completed",H10="PASS"),1,IF(H10="In Progress",0.5,0)) -> 1 | J10: 409 Conflict; 'A Finance expense already exists for claim #...'; duplicate blocked | K10: None | L10: 2026-10-29
A11: ADM-007 | B11: POST | C11: {{baseUrl}}/finance/expenses/from-claim/:claimId | D11: {} | E11: 422 Unprocessable Entity; only APPROVED claims can be converted (PENDING/REJECTED blocked) | F11: Attempt to convert a claim with status PENDING or REJECTED | G11: Claim status PENDING or REJECTED | H11: PASS | I11: =IF(OR(H11="Completed",H11="PASS"),1,IF(H11="In Progress",0.5,0)) -> 1 | J11: 422 Unprocessable Entity; 'Only APPROVED expense claims can be recorded in Finance' | K11: None | L11: 2026-10-29
A12: ADM-008 | B12: POST | C12: {{baseUrl}}/finance/expenses/from-claim/999999 | D12: {} | E12: 404 Not Found; nonexistent claim ID rejected cleanly | F12: Attempt conversion of nonexistent claim ID | G12: Nonexistent claim ID | H12: PASS | I12: =IF(OR(H12="Completed",H12="PASS"),1,IF(H12="In Progress",0.5,0)) -> 1 | J12: 404 Not Found; 'HR Expense claim 999999 not found' | K12: None | L12: 2026-10-29

Sheet Finance Expenses
A1: Finance Module - Operational Expenses
A2: Direct expense lifecycle, approval workflow, payment, and GL posting | As of 29-Oct-26
A4: Test ID | B4: Test Method | C4: URL / Route | D4: Payload / UI Action | E4: Expected Result | F4: Steps to Execute / Verification | G4: Prerequisites / Role | H4: Status | I4: % Done | J4: Actual Result / Evidence | K4: Defect Ref | L4: Last Updated
A5: EXP-001 | B5: POST | C5: {{baseUrl}}/finance/expenses | D5: { "expenseTypeId": 1, "expenseDate": "2026-10-28", "amount": 1500, "vendorName": "Acme Stationery", "notes": "Monthly stationery" } | E5: 201 Created; direct operational expense created with status DRAFT and auto-generated EXP- number | F5: Create operational expense; verify status DRAFT and expenseNumber format | G5: finance.expense.write; valid expenseTypeId | H5: PASS | I5: =IF(OR(H5="Completed",H5="PASS"),1,IF(H5="In Progress",0.5,0)) -> 1 | J5: 201 Created; expense created with status DRAFT; expenseNumber generated as EXP-202610-XXXX | K5: None | L5: 2026-10-29
A6: EXP-002 | B6: GET | C6: {{baseUrl}}/finance/expenses?page=1&limit=10 | D6: (No body) | E6: 200 OK; paginated list of expenses with category details, status, and net amounts | F6: List expenses with pagination parameters (limit <= 100) | G6: finance.expense.read | H6: PASS | I6: =IF(OR(H6="Completed",H6="PASS"),1,IF(H6="In Progress",0.5,0)) -> 1 | J6: 200 OK; returned items list with total count and pagination metadata | K6: None | L6: 2026-10-29
A7: EXP-003 | B7: GET | C7: {{baseUrl}}/finance/expenses/:id | D7: (No body) | E7: 200 OK; returns expense details including vendor, tax breakdown, and linked journal voucher | F7: Retrieve single expense by ID | G7: finance.expense.read | H7: PASS | I7: =IF(OR(H7="Completed",H7="PASS"),1,IF(H7="In Progress",0.5,0)) -> 1 | J7: 200 OK; returned expense entity with complete fields | K7: None | L7: 2026-10-29
A8: EXP-004 | B8: PATCH | C8: {{baseUrl}}/finance/expenses/:id | D8: { "amount": 1650, "notes": "Updated monthly stationery cost" } | E8: 200 OK; amount and notes updated successfully on DRAFT expense | F8: Update an existing DRAFT expense | G8: Expense in status DRAFT | H8: PASS | I8: =IF(OR(H8="Completed",H8="PASS"),1,IF(H8="In Progress",0.5,0)) -> 1 | J8: 200 OK; fields updated and persisted | K8: None | L8: 2026-10-29
A9: EXP-005 | B9: POST | C9: {{baseUrl}}/finance/expenses/:id/submit | D9: (No body) | E9: 201 Created; status transitions from DRAFT to PENDING_APPROVAL | F9: Submit DRAFT expense for managerial approval | G9: Expense in status DRAFT | H9: PASS | I9: =IF(OR(H9="Completed",H9="PASS"),1,IF(H9="In Progress",0.5,0)) -> 1 | J9: 201 Created; status updated to PENDING_APPROVAL | K9: None | L9: 2026-10-29
A10: EXP-006 | B10: POST | C10: {{baseUrl}}/finance/expenses/:id/approve | D10: (No body) | E10: 201 Created; status transitions from PENDING_APPROVAL to APPROVED | F10: Approve pending expense | G10: Expense in status PENDING_APPROVAL | H10: PASS | I10: =IF(OR(H10="Completed",H10="PASS"),1,IF(H10="In Progress",0.5,0)) -> 1 | J10: 201 Created; status updated to APPROVED; ready for payment | K10: None | L10: 2026-10-29
A11: EXP-007 | B11: POST | C11: {{baseUrl}}/finance/expenses/:id/reject | D11: (No body) | E11: 201 Created; status transitions from PENDING_APPROVAL back to DRAFT or CANCELLED | F11: Reject pending expense | G11: Expense in status PENDING_APPROVAL | H11: PASS | I11: =IF(OR(H11="Completed",H11="PASS"),1,IF(H11="In Progress",0.5,0)) -> 1 | J11: 201 Created; status updated per business rules | K11: None | L11: 2026-10-29
A12: EXP-008 | B12: POST | C12: {{baseUrl}}/finance/expenses/:id/pay | D12: { "paymentDate": "2026-10-28", "bankAccountId": 1, "paymentModeId": 1 } | E12: 201 Created; status becomes PAID; creates balanced double-entry journal entry (Debit Expense, Credit Bank); updates bank balance | F12: Pay an approved expense via bank account; verify GL lines and bank balance delta | G12: Expense in status APPROVED; active bank account | H12: PASS | I12: =IF(OR(H12="Completed",H12="PASS"),1,IF(H12="In Progress",0.5,0)) -> 1 | J12: 201 Created; status PAID; journalEntryId linked; balanced voucher generated | K12: None | L12: 2026-10-29
A13: EXP-009 | B13: PATCH | C13: {{baseUrl}}/finance/expenses/:id | D13: { "amount": 9999 } | E13: 422 Unprocessable Entity; modifying a PAID expense is strictly rejected | F13: Attempt to patch an expense after it has been marked PAID | G13: Expense in status PAID | H13: PASS | I13: =IF(OR(H13="Completed",H13="PASS"),1,IF(H13="In Progress",0.5,0)) -> 1 | J13: 422 Unprocessable Entity; 'Cannot modify a paid expense record' | K13: None | L13: 2026-10-29
A14: EXP-010 | B14: POST | C14: {{baseUrl}}/finance/expenses/:id/cancel | D14: (No body) | E14: 201 Created; cancels an approved or draft expense before payment | F14: Cancel an unpaid expense | G14: Expense not PAID | H14: PASS | I14: =IF(OR(H14="Completed",H14="PASS"),1,IF(H14="In Progress",0.5,0)) -> 1 | J14: 201 Created; status becomes CANCELLED | K14: None | L14: 2026-10-29
A15: EXP-011 | B15: POST | C15: {{baseUrl}}/finance/expenses | D15: { "expenseTypeId": 1, "expenseDate": "2099-12-31", "amount": 100 } | E15: 400 Bad Request; future expense dates rejected by business validation | F15: Submit expense with future date | G15: Validation rule | H15: PASS | I15: =IF(OR(H15="Completed",H15="PASS"),1,IF(H15="In Progress",0.5,0)) -> 1 | J15: 400 Bad Request; 'Expense date cannot be in the future' | K15: None | L15: 2026-10-29
A16: EXP-012 | B16: DELETE | C16: {{baseUrl}}/finance/expenses/:id | D16: (No body) | E16: 200 OK / 204; soft-deletes a DRAFT or CANCELLED expense (deletedAt set); permanent purge blocked | F16: Soft-delete test draft expense; verify deletedAt populated without SQL DROP/DELETE | G16: DRAFT expense | H16: PASS | I16: =IF(OR(H16="Completed",H16="PASS"),1,IF(H16="In Progress",0.5,0)) -> 1 | J16: 200 OK; soft deleted; deletedAt timestamp set; historical audit preserved | K16: None | L16: 2026-10-29

Sheet Expense Category Consistency
A1: Category Consistency - Mapping & Auto-Provisioning
A2: Explicit mapping: Medical, Travel, Food, Accommodation, Office Supplies, Other | As of 29-Oct-26
A4: Test ID | B4: Test Method | C4: URL / Route | D4: Payload / UI Action | E4: Expected Result | F4: Steps to Execute / Verification | G4: Prerequisites / Role | H4: Status | I4: % Done | J4: Actual Result / Evidence | K4: Defect Ref | L4: Last Updated
A5: CAT-001 | B5: POST | C5: {{baseUrl}}/finance/expenses/from-claim/:claimId | D5: Claim #8 with category 'Medical' | E5: Mapped to Finance Expense category 'Medical' (exact match or auto-provisioned canonical) | F5: Verify category resolution for Medical claim; verify persisted FinanceMasterListItem ID | G5: Claim category: Medical | H5: PASS | I5: =IF(OR(H5="Completed",H5="PASS"),1,IF(H5="In Progress",0.5,0)) -> 1 | J5: Mapped to 'Medical' (ID 11); verified in EXP-202610-0015 and unit tests | K5: None | L5: 2026-10-29
A6: CAT-002 | B6: POST | C6: {{baseUrl}}/finance/expenses/from-claim/:claimId | D6: Claim #3 with category 'Travel' | E6: Mapped to canonical Finance Expense category 'Travel & Lodging' | F6: Verify category resolution for Travel claim | G6: Claim category: Travel | H6: PASS | I6: =IF(OR(H6="Completed",H6="PASS"),1,IF(H6="In Progress",0.5,0)) -> 1 | J6: Mapped to 'Travel & Lodging' (ID 2); verified in EXP-202610-0011 | K6: None | L6: 2026-10-29
A7: CAT-003 | B7: POST | C7: {{baseUrl}}/finance/expenses/from-claim/:claimId | D7: Claim #6 with category 'Food' | E7: Mapped to canonical Finance Expense category 'Food & Meals' | F7: Verify category resolution for Food claim | G7: Claim category: Food | H7: PASS | I7: =IF(OR(H7="Completed",H7="PASS"),1,IF(H7="In Progress",0.5,0)) -> 1 | J7: Mapped to 'Food & Meals' (ID 12); verified in EXP-202610-0012 | K7: None | L7: 2026-10-29
A8: CAT-004 | B8: POST | C8: {{baseUrl}}/finance/expenses/from-claim/:claimId | D8: Claim #4 with category 'Accommodation' | E8: Mapped to canonical Finance Expense category 'Accommodation' | F8: Verify category resolution for Accommodation claim | G8: Claim category: Accommodation | H8: PASS | I8: =IF(OR(H8="Completed",H8="PASS"),1,IF(H8="In Progress",0.5,0)) -> 1 | J8: Mapped to 'Accommodation' (ID 13); verified in EXP-202610-0010 | K8: None | L8: 2026-10-29
A9: CAT-005 | B9: POST | C9: {{baseUrl}}/finance/expenses/from-claim/:claimId | D9: Claim with category 'Office Supplies' | E9: Mapped to canonical Finance Expense category 'Office Supplies' | F9: Verify category resolution for Office Supplies claim | G9: Claim category: Office Supplies | H9: PASS | I9: =IF(OR(H9="Completed",H9="PASS"),1,IF(H9="In Progress",0.5,0)) -> 1 | J9: Mapped to 'Office Supplies' (ID 1); verified in test suites | K9: None | L9: 2026-10-29
A10: CAT-006 | B10: POST | C10: {{baseUrl}}/finance/expenses/from-claim/:claimId | D10: Claim with category 'Other' | E10: Mapped to canonical Finance Expense category 'Other' | F10: Verify category resolution for Other claim | G10: Claim category: Other | H10: PASS | I10: =IF(OR(H10="Completed",H10="PASS"),1,IF(H10="In Progress",0.5,0)) -> 1 | J10: Mapped to 'Other' (ID 14); verified in test suites | K10: None | L10: 2026-10-29
A11: CAT-007 | B11: INTERNAL | C11: ExpensesService.resolveExpenseTypeForClaim() | D11: New organization without seeded categories | E11: Auto-provisions the canonical category in FinanceMasterListItem for that tenant | F11: Simulate unseeded organization; verify auto-provisioning log and DB insert | G11: Valid category mapping key | H11: PASS | I11: =IF(OR(H11="Completed",H11="PASS"),1,IF(H11="In Progress",0.5,0)) -> 1 | J11: Verified in expenses.service.spec.ts: auto-provisioned Medical, Food & Meals, Accommodation, Other | K11: None | L11: 2026-10-29
A12: CAT-008 | B12: INTERNAL | C12: ExpensesService.resolveExpenseTypeForClaim() | D12: Claim with unsupported category 'CryptoTokens' | E12: Throws BusinessRuleViolationException; NEVER silently defaults to Office Supplies | F12: Test conversion with unsupported category; verify failure is safe and explicit | G12: Unsupported category string | H12: PASS | I12: =IF(OR(H12="Completed",H12="PASS"),1,IF(H12="In Progress",0.5,0)) -> 1 | J12: Throws BusinessRuleViolationException: 'Failed to map expense claim category...'; zero silent fallback | K12: None | L12: 2026-10-29

Sheet Expense Reimbursement
A1: Finance Module - Employee Reimbursements
A2: Disbursement of converted claims via bank account and ledger synchronization | As of 29-Oct-26
A4: Test ID | B4: Test Method | C4: URL / Route | D4: Payload / UI Action | E4: Expected Result | F4: Steps to Execute / Verification | G4: Prerequisites / Role | H4: Status | I4: % Done | J4: Actual Result / Evidence | K4: Defect Ref | L4: Last Updated
A5: REIM-001 | B5: POST | C5: {{baseUrl}}/finance/expenses/:id/pay | D5: { "paymentDate": "2026-10-28", "bankAccountId": 1, "paymentModeId": 1 } | E5: 201 Created; status transitions to PAID; creates bank DEBIT transaction and balanced GL voucher | F5: Disburse reimbursement for converted claim EXP-202610-0015 (₹5000) via HDFC Bank | G5: Converted claim expense with status APPROVED | H5: PASS | I5: =IF(OR(H5="Completed",H5="PASS"),1,IF(H5="In Progress",0.5,0)) -> 1 | J5: 201 Created; status PAID; Bank Txn #32 (DEBIT ₹5000, BalAfter: 21342.22) created | K5: None | L5: 2026-10-29
A6: REIM-002 | B6: GET | C6: {{baseUrl}}/finance/bank-transactions?bankAccountId=1&limit=5 | D6: (No body) | E6: 200 OK; bank transaction verifies exactly one DEBIT movement for the reimbursement amount | F6: Inspect statement feed for bankAccountId 1; verify transaction description and direction | G6: Bank account 1 | H6: PASS | I6: =IF(OR(H6="Completed",H6="PASS"),1,IF(H6="In Progress",0.5,0)) -> 1 | J6: 200 OK; Txn #32 description: 'Expense disbursement EXP-202610-0015 to Reimbursement: employee demo' | K6: None | L6: 2026-10-29
A7: REIM-003 | B7: GET | C7: {{baseUrl}}/finance/bank-accounts/1 | D7: (No body) | E7: 200 OK; bank account currentBalance decreased by exactly the reimbursement amount | F7: Check bank balance before and after payout | G7: Bank account 1 | H7: PASS | I7: =IF(OR(H7="Completed",H7="PASS"),1,IF(H7="In Progress",0.5,0)) -> 1 | J7: 200 OK; currentBalance updated atomically by -₹5000 in database | K7: None | L7: 2026-10-29
A8: REIM-004 | B8: GET | C8: {{baseUrl}}/finance/journal-entries/:id | D8: (No body) | E8: 200 OK; journal voucher has Line 0 (Debit Expense), Line 1 (Credit Bank Asset); Total Debit == Total Credit | F8: Retrieve journal voucher generated during reimbursement | G8: Linked journalEntryId | H8: PASS | I8: =IF(OR(H8="Completed",H8="PASS"),1,IF(H8="In Progress",0.5,0)) -> 1 | J8: 200 OK; balanced voucher JV-202610-XXXX confirmed; debit ₹5000, credit ₹5000 | K8: None | L8: 2026-10-29
A9: REIM-005 | B9: POST | C9: {{baseUrl}}/finance/expenses/:id/pay | D9: { "paymentDate": "2026-10-28", "bankAccountId": 1 } | E9: 422 Unprocessable Entity; attempting to reimburse an already paid expense is blocked | F9: Retry payout request on an expense with status PAID; verify double-disbursement protection | G9: Expense already PAID | H9: PASS | I9: =IF(OR(H9="Completed",H9="PASS"),1,IF(H9="In Progress",0.5,0)) -> 1 | J9: 422 Unprocessable Entity; 'Expense is already marked as paid'; zero duplicate payout | K9: None | L9: 2026-10-29
A10: REIM-006 | B10: GET | C10: {{baseUrl}}/finance/expenses/:id | D10: (No body) | E10: 200 OK; expense retains vendorName with employee name/code and links to original hrExpenseClaimId | F10: Verify audit traceability from Finance Expense back to employee claim | G10: Converted expense ID | H10: PASS | I10: =IF(OR(H10="Completed",H10="PASS"),1,IF(H10="In Progress",0.5,0)) -> 1 | J10: 200 OK; vendorName 'Reimbursement: employee demo (EMP-000002)'; hrExpenseClaimId: 8 preserved | K10: None | L10: 2026-10-29

Sheet Payments Received
A1: Finance Module - Customer Payments Received
A2: Bank Inflow verification (CREDIT transaction), multi-invoice allocation, and void reversal | As of 29-Oct-26
A4: Test ID | B4: Test Method | C4: URL / Route | D4: Payload / UI Action | E4: Expected Result | F4: Steps to Execute / Verification | G4: Prerequisites / Role | H4: Status | I4: % Done | J4: Actual Result / Evidence | K4: Defect Ref | L4: Last Updated
